<?xml version="1.0" encoding="utf-8"?>
<!-- This URDF was automatically created by SolidWorks to URDF Exporter! Originally created by
Stephen Brawner (brawner@gmail.com) 
     Commit Version: 1.6.0-4-g7f85cfe  Build Version: 1.6.7995.38578
     For more information, please see http://wiki.ros.org/sw_urdf_exporter -->
<robot
  name="origaker_fix">
  <link
    name="base_link">
    <inertial>
      <origin xyz="0.11061772 -0.01525057 0.22844154" />
      <mass value="0.00200000" />
      <inertia ixx="0.00000862" ixy="-0.00000497" ixz="-0.00000000" iyy="0.00000809"
        iyz="0.00000000" izz="0.00001659" />
    </inertial>

    <visual>
      <origin
        xyz="0 0 0"
        rpy="0 0 0" />
      <geometry>
        <mesh
          filename="/home/thedevmanek/Documents/origaker_pybullet/meshes/base_link.STL" />
      </geometry>
      <material
        name="">
        <color
          rgba="0.50196 0.50196 1 1" />
      </material>
    </visual>
    <collision>
      <origin
        xyz="0 0 0"
        rpy="0 0 0" />
      <geometry>
        <mesh
          filename="/home/thedevmanek/Documents/origaker_pybullet/meshes/base_link.STL" />
      </geometry>
    </collision>
  </link>
  <link
    name="tr1">
    <inertial>
      <origin xyz="0.02513278 -0.00000000 0.00753126" />
      <mass value="0.00500000" />
      <inertia ixx="0.00000012" ixy="-0.00000000" ixz="0.00000000" iyy="0.00000136"
        iyz="-0.00000000" izz="0.00000136" />
    </inertial>

    <visual>
      <origin
        xyz="0 0 0"
        rpy="0 0 0" />
      <geometry>
        <mesh
          filename="/home/thedevmanek/Documents/origaker_pybullet/meshes/tr1.STL" />
      </geometry>
      <material
        name="">
        <color
          rgba="0.50196 0.50196 0.50196 1" />
      </material>
    </visual>
    <collision>
      <origin
        xyz="0 0 0"
        rpy="0 0 0" />
      <geometry>
        <mesh
          filename="/home/thedevmanek/Documents/origaker_pybullet/meshes/tr1.STL" />
      </geometry>
    </collision>
  </link>
  <joint
    name="base_tr1"
    type="revolute">
    <origin
      xyz="0.10342 -0.13222 0.219"
      rpy="8.0926E-05 -0.00068912 -0.87574" />
    <parent
      link="base_link" />
    <child
      link="tr1" />
    <axis
      xyz="0 0 1" />
    <limit
      lower="-2.6"
      upper="3.6"
      effort="30"
      velocity="5" />


  </joint>
  <link
    name="tr2">
    <inertial>
      <origin xyz="0.02945627 0.00000000 0.00004065" />
      <mass value="0.00580000" />
      <inertia ixx="0.00000014" ixy="-0.00000000" ixz="-0.00000000" iyy="0.00000209"
        iyz="-0.00000000" izz="0.00000203" />
    </inertial>

    <visual>
      <origin
        xyz="0 0 0"
        rpy="0 0 0" />
      <geometry>
        <mesh
          filename="/home/thedevmanek/Documents/origaker_pybullet/meshes/tr2.STL" />
      </geometry>
      <material
        name="">
        <color
          rgba="0.50196 0.50196 0.50196 1" />
      </material>
    </visual>
    <collision>
      <origin
        xyz="0 0 0"
        rpy="0 0 0" />
      <geometry>
        <mesh
          filename="/home/thedevmanek/Documents/origaker_pybullet/meshes/tr2.STL" />
      </geometry>
    </collision>
  </link>
  <joint
    name="tr1_tr2"
    type="revolute">
    <origin
      xyz="0.046 0 0.0074954"
      rpy="0 0 0" />
    <parent
      link="tr1" />
    <child
      link="tr2" />
    <axis
      xyz="0 1 0" />
    <limit
      lower="-2.6"
      upper="3.6"
      effort="30"
      velocity="5" />


  </joint>
  <link
    name="tr3">
    <inertial>
      <origin xyz="0.04764141 0.00001190 0.00001488" />
      <mass value="0.01000000" />
      <inertia ixx="0.00000019" ixy="-0.00000000" ixz="-0.00000000" iyy="0.00001019"
        iyz="0.00000000" izz="0.00001015" />
    </inertial>

    <visual>
      <origin
        xyz="0 0 0"
        rpy="0 0 0" />
      <geometry>
        <mesh
          filename="/home/thedevmanek/Documents/origaker_pybullet/meshes/tr3.STL" />
      </geometry>
      <material
        name="">
        <color
          rgba="0.50196 0.50196 0.50196 1" />
      </material>
    </visual>
    <collision>
      <origin
        xyz="0 0 0"
        rpy="0 0 0" />
      <geometry>
        <mesh
          filename="/home/thedevmanek/Documents/origaker_pybullet/meshes/tr3.STL" />
      </geometry>
    </collision>
  </link>
  <joint
    name="tr2_tr3"
    type="revolute">
    <origin
      xyz="0.05385 0 0"
      rpy="0 0 0" />
    <parent
      link="tr2" />
    <child
      link="tr3" />
    <axis
      xyz="0 1 0" />
    <limit
      lower="-2.6"
      upper="3.6"
      effort="30"
      velocity="5" />


  </joint>

  <link
    name="tl1">
    <inertial>
      <origin xyz="0.02513278 -0.00000000 0.00753126" />
      <mass value="0.00500000" />
      <inertia ixx="0.00000012" ixy="-0.00000000" ixz="0.00000000" iyy="0.00000136"
        iyz="-0.00000000" izz="0.00000136" />
    </inertial>

    <visual>
      <origin
        xyz="0 0 0"
        rpy="0 0 0" />
      <geometry>
        <mesh
          filename="/home/thedevmanek/Documents/origaker_pybullet/meshes/tl1.STL" />
      </geometry>
      <material
        name="">
        <color
          rgba="0.50196 0.50196 0.50196 1" />
      </material>
    </visual>
    <collision>
      <origin
        xyz="0 0 0"
        rpy="0 0 0" />
      <geometry>
        <mesh
          filename="/home/thedevmanek/Documents/origaker_pybullet/meshes/tl1.STL" />
      </geometry>
    </collision>
  </link>
  <joint
    name="base_tl1"
    type="revolute">
    <origin
      xyz="-0.0054343 -0.028997 0.21894"
      rpy="0 0 2.5701" />
    <parent
      link="base_link" />
    <child
      link="tl1" />
    <axis
      xyz="0 0 -1" />

    <limit
      lower="-2.6"
      upper="3.6"
      effort="30"
      velocity="5" />


  </joint>
  <link
    name="tl2">
    <inertial>
      <origin xyz="0.02945627 0.00000000 0.00004065" />
      <mass value="0.00580000" />
      <inertia ixx="0.00000014" ixy="-0.00000000" ixz="-0.00000000" iyy="0.00000209"
        iyz="-0.00000000" izz="0.00000203" />
    </inertial>

    <visual>
      <origin
        xyz="0 0 0"
        rpy="0 0 0" />
      <geometry>
        <mesh
          filename="/home/thedevmanek/Documents/origaker_pybullet/meshes/tl2.STL" />
      </geometry>
      <material
        name="">
        <color
          rgba="0.501960784313725 0.501960784313725 0.501960784313725 1" />
      </material>
    </visual>
    <collision>
      <origin
        xyz="0 0 0"
        rpy="0 0 0" />
      <geometry>
        <mesh
          filename="/home/thedevmanek/Documents/origaker_pybullet/meshes/tl2.STL" />
      </geometry>
    </collision>
  </link>
  <joint
    name="tl1_tl2"
    type="revolute">
    <origin
      xyz="0.046 0 0.0075"
      rpy="0 0 0" />
    <parent
      link="tl1" />
    <child
      link="tl2" />
    <axis
      xyz="0 1 0" />
    <limit
      lower="-2.6"
      upper="3.6"
      effort="30"
      velocity="5" />


  </joint>
  <link
    name="tl3">
    <inertial>
      <origin xyz="0.04764141 0.00001190 0.00001488" />
      <mass value="0.01000000" />
      <inertia ixx="0.00000019" ixy="-0.00000000" ixz="-0.00000000" iyy="0.00001019"
        iyz="0.00000000" izz="0.00001015" />
    </inertial>

    <visual>
      <origin
        xyz="0 0 0"
        rpy="0 0 0" />
      <geometry>
        <mesh
          filename="/home/thedevmanek/Documents/origaker_pybullet/meshes/tl3.STL" />
      </geometry>
      <material
        name="">
        <color
          rgba="0.50196 0.50196 0.50196 1" />
      </material>
    </visual>
    <collision>
      <origin
        xyz="0 0 0"
        rpy="0 0 0" />
      <geometry>
        <mesh
          filename="/home/thedevmanek/Documents/origaker_pybullet/meshes/tl3.STL" />
      </geometry>
    </collision>
  </link>
  <joint
    name="tl2_tl3"
    type="revolute">
    <origin
      xyz="0.0538500000000001 0 0"
      rpy="0 0 0" />
    <parent
      link="tl2" />
    <child
      link="tl3" />
    <axis
      xyz="0 1 0" />
    <limit
      lower="-2.6"
      upper="3.6"
      effort="30"
      velocity="5" />


  </joint>
  <link
    name="br1">
    <inertial>
      <origin xyz="0.02513278 -0.00000000 0.00753126" />
      <mass value="0.00500000" />
      <inertia ixx="0.00000012" ixy="-0.00000000" ixz="0.00000000" iyy="0.00000136"
        iyz="-0.00000000" izz="0.00000136" />
    </inertial>

    <visual>
      <origin
        xyz="0 0 0"
        rpy="0 0 0" />
      <geometry>
        <mesh
          filename="/home/thedevmanek/Documents/origaker_pybullet/meshes/br1.STL" />
      </geometry>
      <material
        name="">
        <color
          rgba="0.50196 0.50196 0.50196 1" />
      </material>
    </visual>
    <collision>
      <origin
        xyz="0 0 0"
        rpy="0 0 0" />
      <geometry>
        <mesh
          filename="/home/thedevmanek/Documents/origaker_pybullet/meshes/br1.STL" />
      </geometry>
    </collision>
  </link>
  <joint
    name="base_br1"
    type="revolute">
    <origin
      xyz="0.22727 -0.0016027 0.219"
      rpy="0.00019673 -0.00066538 -1.0463" />
    <parent
      link="base_link" />
    <child
      link="br1" />
    <axis
      xyz="0 0 1" />

    <limit
      lower="-2.6"
      upper="3.6"
      effort="30"
      velocity="5" />


  </joint>
  <link
    name="br2">
    <inertial>
      <origin xyz="0.02945627 0.00000000 0.00004065" />
      <mass value="0.00580000" />
      <inertia ixx="0.00000014" ixy="-0.00000000" ixz="-0.00000000" iyy="0.00000209"
        iyz="-0.00000000" izz="0.00000203" />
    </inertial>

    <visual>
      <origin
        xyz="0 0 0"
        rpy="0 0 0" />
      <geometry>
        <mesh
          filename="/home/thedevmanek/Documents/origaker_pybullet/meshes/br2.STL" />
      </geometry>
      <material
        name="">
        <color
          rgba="0.501960784313725 0.501960784313725 0.501960784313725 1" />
      </material>
    </visual>
    <collision>
      <origin
        xyz="0 0 0"
        rpy="0 0 0" />
      <geometry>
        <mesh
          filename="/home/thedevmanek/Documents/origaker_pybullet/meshes/br2.STL" />
      </geometry>
    </collision>
  </link>
  <joint
    name="br1_br2"
    type="revolute">
    <origin
      xyz="0.046 0 0.0074964"
      rpy="0 0 0" />
    <parent
      link="br1" />
    <child
      link="br2" />
    <axis
      xyz="0 1 0" />
    <limit
      lower="-2.6"
      upper="3.6"
      effort="30"
      velocity="5" />


  </joint>
  <link
    name="br3">
    <inertial>
      <origin xyz="0.04764141 0.00001190 0.00001488" />
      <mass value="0.01000000" />
      <inertia ixx="0.00000019" ixy="-0.00000000" ixz="-0.00000000" iyy="0.00001019"
        iyz="0.00000000" izz="0.00001015" />
    </inertial>

    <visual>
      <origin
        xyz="0 0 0"
        rpy="0 0 0" />
      <geometry>
        <mesh
          filename="/home/thedevmanek/Documents/origaker_pybullet/meshes/br3.STL" />
      </geometry>
      <material
        name="">
        <color
          rgba="0.50196 0.50196 0.50196 1" />
      </material>
    </visual>
    <collision>
      <origin
        xyz="0 0 0"
        rpy="0 0 0" />
      <geometry>
        <mesh
          filename="/home/thedevmanek/Documents/origaker_pybullet/meshes/br3.STL" />
      </geometry>
    </collision>
  </link>
  <joint
    name="br2_br3"
    type="revolute">
    <origin
      xyz="0.0538500000000001 0 0"
      rpy="0 0 0" />
    <parent
      link="br2" />
    <child
      link="br3" />
    <axis
      xyz="0 1 0" />
    <limit
      lower="-2.6"
      upper="3.6"
      effort="30"
      velocity="5" />


  </joint>
  <link
    name="bl1">
    <inertial>
      <origin xyz="0.02513278 -0.00000000 0.00753126" />
      <mass value="0.00500000" />
      <inertia ixx="0.00000012" ixy="-0.00000000" ixz="0.00000000" iyy="0.00000136"
        iyz="-0.00000000" izz="0.00000136" />
    </inertial>

    <visual>
      <origin
        xyz="0 0 0"
        rpy="0 0 0" />
      <geometry>
        <mesh
          filename="/home/thedevmanek/Documents/origaker_pybullet/meshes/bl1.STL" />
      </geometry>
      <material
        name="">
        <color
          rgba="1 1 1 1" />
      </material>
    </visual>
    <collision>
      <origin
        xyz="0 0 0"
        rpy="0 0 0" />
      <geometry>
        <mesh
          filename="/home/thedevmanek/Documents/origaker_pybullet/meshes/bl1.STL" />
      </geometry>
    </collision>
  </link>
  <joint
    name="base_bl1"
    type="revolute">
    <origin
      xyz="0.11842 0.10162 0.21894"
      rpy="0 0 2.4692" />
    <parent
      link="base_link" />
    <child
      link="bl1" />
    <axis
      xyz="0 0 -1" />

    <limit
      lower="-2.6"
      upper="3.6"
      effort="30"
      velocity="5" />


  </joint>
  <link
    name="bl2">
    <inertial>
      <origin xyz="0.02945627 0.00000000 0.00004065" />
      <mass value="0.00580000" />
      <inertia ixx="0.00000014" ixy="-0.00000000" ixz="-0.00000000" iyy="0.00000209"
        iyz="-0.00000000" izz="0.00000203" />
    </inertial>

    <visual>
      <origin
        xyz="0 0 0"
        rpy="0 0 0" />
      <geometry>
        <mesh
          filename="/home/thedevmanek/Documents/origaker_pybullet/meshes/bl2.STL" />
      </geometry>
      <material
        name="">
        <color
          rgba="0.50196 0.50196 0.50196 1" />
      </material>
    </visual>
    <collision>
      <origin
        xyz="0 0 0"
        rpy="0 0 0" />
      <geometry>
        <mesh
          filename="/home/thedevmanek/Documents/origaker_pybullet/meshes/bl2.STL" />
      </geometry>
    </collision>
  </link>
  <joint
    name="bl1_bl2"
    type="revolute">
    <origin
      xyz="0.046 0 0.0075"
      rpy="0 0 0" />
    <parent
      link="bl1" />
    <child
      link="bl2" />
    <axis
      xyz="0 1 0" />
    <limit
      lower="-2.6"
      upper="3.6"
      effort="30"
      velocity="5" />


  </joint>
  <link
    name="bl3">
    <inertial>
      <origin xyz="0.04764141 0.00001190 0.00001488" />
      <mass value="0.01000000" />
      <inertia ixx="0.00000019" ixy="-0.00000000" ixz="-0.00000000" iyy="0.00001019"
        iyz="0.00000000" izz="0.00001015" />
    </inertial>

    <visual>
      <origin
        xyz="0 0 0"
        rpy="0 0 0" />
      <geometry>
        <mesh
          filename="/home/thedevmanek/Documents/origaker_pybullet/meshes/bl3.STL" />
      </geometry>
      <material
        name="">
        <color
          rgba="0.50196 0.50196 0.50196 1" />
      </material>
    </visual>
    <collision>
      <origin
        xyz="0 0 0"
        rpy="0 0 0" />
      <geometry>
        <mesh
          filename="/home/thedevmanek/Documents/origaker_pybullet/meshes/bl3.STL" />
      </geometry>
    </collision>
  </link>
  <joint
    name="bl2_bl3"
    type="revolute">
    <origin
      xyz="0.05385 0 0"
      rpy="0 0 0" />
    <parent
      link="bl2" />
    <child
      link="bl3" />
    <axis
      xyz="0 1 0" />
    <limit
      lower="-2.6"
      upper="3.6"
      effort="30"
      velocity="5" />


  </joint>
  <gazebo reference="bl1">
    <mu1>1</mu1>
    <mu2>1</mu2>
    <fdir1>1 0 0</fdir1>
    <maxVel>0.01</maxVel>
    <!-- <minDepth>0.007</minDepth> -->
    <kp>10000</kp>
    <kd>1</kd>

  </gazebo>
  <gazebo reference="bl2">
    <mu1>1</mu1>
    <mu2>1</mu2>
    <fdir1>1 0 0</fdir1>
    <maxVel>0.01</maxVel>
    <!-- <minDepth>0.007</minDepth> -->
    <kp>10000</kp>
    <kd>1</kd>

  </gazebo>
  <gazebo reference="bl3">
    <mu1>1</mu1>
    <mu2>1</mu2>
    <fdir1>1 0 0</fdir1>
    <maxVel>0.01</maxVel>
    <!-- <minDepth>0.007</minDepth> -->
    <kp>10000</kp>
    <kd>1</kd>

  </gazebo>

  <gazebo reference="tl1">
    <mu1>1</mu1>
    <mu2>1</mu2>
    <fdir1>1 0 0</fdir1>
    <maxVel>0.01</maxVel>
    <!-- <minDepth>0.007</minDepth> -->
    <kp>10000</kp>
    <kd>1</kd>

  </gazebo>
  <gazebo reference="tl2">
    <mu1>1</mu1>
    <mu2>1</mu2>
    <fdir1>1 0 0</fdir1>
    <maxVel>0.01</maxVel>
    <!-- <minDepth>0.007</minDepth> -->
    <kp>10000</kp>
    <kd>1</kd>

  </gazebo>
  <gazebo reference="tl3">
    <mu1>1</mu1>
    <mu2>1</mu2>
    <fdir1>1 0 0</fdir1>
    <maxVel>0.01</maxVel>
    <!-- <minDepth>0.007</minDepth> -->
    <kp>10000</kp>
    <kd>1</kd>

  </gazebo>

  <gazebo reference="tr1">
    <mu1>1</mu1>
    <mu2>1</mu2>
    <fdir1>1 0 0</fdir1>
    <maxVel>0.01</maxVel>
    <!-- <minDepth>0.007</minDepth> -->
    <kp>10000</kp>
    <kd>1</kd>

  </gazebo>
  <gazebo reference="tr2">
    <mu1>1</mu1>
    <mu2>1</mu2>
    <fdir1>1 0 0</fdir1>
    <maxVel>0.01</maxVel>
    <!-- <minDepth>0.007</minDepth> -->
    <kp>10000</kp>
    <kd>1</kd>

  </gazebo>
  <gazebo reference="tr3">
    <mu1>1</mu1>
    <mu2>1</mu2>
    <fdir1>1 0 0</fdir1>
    <maxVel>0.01</maxVel>
    <!-- <minDepth>0.007</minDepth> -->
    <kp>10000</kp>
    <kd>1</kd>

  </gazebo>

  <gazebo reference="br1">
    <mu1>1</mu1>
    <mu2>1</mu2>
    <fdir1>1 0 0</fdir1>
    <maxVel>0.01</maxVel>
    <!-- <minDepth>0.007</minDepth> -->
    <kp>10000</kp>
    <kd>1</kd>

  </gazebo>
  <gazebo reference="br2">
    <mu1>1</mu1>
    <mu2>1</mu2>
    <fdir1>1 0 0</fdir1>
    <maxVel>0.01</maxVel>
    <!-- <minDepth>0.007</minDepth> -->
    <kp>10000</kp>
    <kd>1</kd>

  </gazebo>
  <gazebo reference="br3">
    <mu1>1</mu1>
    <mu2>1</mu2>
    <fdir1>1 0 0</fdir1>
    <maxVel>0.01</maxVel>
    <!-- <minDepth>0.007</minDepth> -->
    <kp>10000</kp>
    <kd>1</kd>

  </gazebo>

  <gazebo>
    <plugin name="gazebo_ros_control" filename="libgazebo_ros_control.so">
      <robotNamespace>/origaker</robotNamespace>
    </plugin>
  </gazebo>
  <transmission name="trans_base_tr1">
    <type>transmission_interface/SimpleTransmission</type>
    <joint name="base_tr1">
      <hardwareInterface>hardware_interface/PositionJointInterface</hardwareInterface>
    </joint>
    <actuator name="motor_base_tr1">
      <hardwareInterface>hardware_interface/PositionJointInterface</hardwareInterface>
      <mechanicalReduction>1</mechanicalReduction>
    </actuator>
  </transmission>
  <transmission name="trans_tr1_tr2">
    <type>transmission_interface/SimpleTransmission</type>
    <joint name="tr1_tr2">
      <hardwareInterface>hardware_interface/PositionJointInterface</hardwareInterface>
    </joint>
    <actuator name="motor_tr1_tr2">
      <hardwareInterface>hardware_interface/PositionJointInterface</hardwareInterface>
      <mechanicalReduction>1</mechanicalReduction>
    </actuator>
  </transmission>
  <transmission name="trans_tr2_tr3">
    <type>transmission_interface/SimpleTransmission</type>
    <joint name="tr2_tr3">
      <hardwareInterface>hardware_interface/PositionJointInterface</hardwareInterface>
    </joint>
    <actuator name="motor_tr2_tr3">
      <hardwareInterface>hardware_interface/PositionJointInterface</hardwareInterface>
      <mechanicalReduction>1</mechanicalReduction>
    </actuator>
  </transmission>
  <transmission name="trans_base_br1">
    <type>transmission_interface/SimpleTransmission</type>
    <joint name="base_br1">
      <hardwareInterface>hardware_interface/PositionJointInterface</hardwareInterface>
    </joint>
    <actuator name="motor_base_br1">
      <hardwareInterface>hardware_interface/PositionJointInterface</hardwareInterface>
      <mechanicalReduction>1</mechanicalReduction>
    </actuator>
  </transmission>
  <transmission name="trans_br1_br2">
    <type>transmission_interface/SimpleTransmission</type>
    <joint name="br1_br2">
      <hardwareInterface>hardware_interface/PositionJointInterface</hardwareInterface>
    </joint>
    <actuator name="motor_br1_br2">
      <hardwareInterface>hardware_interface/PositionJointInterface</hardwareInterface>
      <mechanicalReduction>1</mechanicalReduction>
    </actuator>
  </transmission>
  <transmission name="trans_br2_br3">
    <type>transmission_interface/SimpleTransmission</type>
    <joint name="br2_br3">
      <hardwareInterface>hardware_interface/PositionJointInterface</hardwareInterface>
    </joint>
    <actuator name="motor_br2_br3">
      <hardwareInterface>hardware_interface/PositionJointInterface</hardwareInterface>
      <mechanicalReduction>1</mechanicalReduction>
    </actuator>
  </transmission>

  <transmission name="trans_base_bl1">
    <type>transmission_interface/SimpleTransmission</type>
    <joint name="base_bl1">
      <hardwareInterface>hardware_interface/PositionJointInterface</hardwareInterface>
    </joint>
    <actuator name="motor_base_bl1">
      <hardwareInterface>hardware_interface/PositionJointInterface</hardwareInterface>
      <mechanicalReduction>1</mechanicalReduction>
    </actuator>
  </transmission>
  <transmission name="trans_bl1_bl2">
    <type>transmission_interface/SimpleTransmission</type>
    <joint name="bl1_bl2">
      <hardwareInterface>hardware_interface/PositionJointInterface</hardwareInterface>
    </joint>
    <actuator name="motor_bl1_bl2">
      <hardwareInterface>hardware_interface/PositionJointInterface</hardwareInterface>
      <mechanicalReduction>1</mechanicalReduction>
    </actuator>
  </transmission>
  <transmission name="trans_bl2_bl3">
    <type>transmission_interface/SimpleTransmission</type>
    <joint name="bl2_bl3">
      <hardwareInterface>hardware_interface/PositionJointInterface</hardwareInterface>
    </joint>
    <actuator name="motor_bl2_bl3">
      <hardwareInterface>hardware_interface/PositionJointInterface</hardwareInterface>
      <mechanicalReduction>1</mechanicalReduction>
    </actuator>
  </transmission>

  <transmission name="trans_base_tl1">
    <type>transmission_interface/SimpleTransmission</type>
    <joint name="base_tl1">
      <hardwareInterface>hardware_interface/PositionJointInterface</hardwareInterface>
    </joint>
    <actuator name="motor_base_tl1">
      <hardwareInterface>hardware_interface/PositionJointInterface</hardwareInterface>
      <mechanicalReduction>1</mechanicalReduction>
    </actuator>
  </transmission>
  <transmission name="trans_tl1_tl2">
    <type>transmission_interface/SimpleTransmission</type>
    <joint name="tl1_tl2">
      <hardwareInterface>hardware_interface/PositionJointInterface</hardwareInterface>
    </joint>
    <actuator name="motor_tl1_tl2">
      <hardwareInterface>hardware_interface/PositionJointInterface</hardwareInterface>
      <mechanicalReduction>1</mechanicalReduction>
    </actuator>
  </transmission>
  <transmission name="trans_tl2_tl3">
    <type>transmission_interface/SimpleTransmission</type>
    <joint name="tl2_tl3">
      <hardwareInterface>hardware_interface/PositionJointInterface</hardwareInterface>
    </joint>
    <actuator name="motor_tl2_tl3">
      <hardwareInterface>hardware_interface/PositionJointInterface</hardwareInterface>
      <mechanicalReduction>1</mechanicalReduction>
    </actuator>
  </transmission>

</robot>